INFO:werkzeug:127.0.0.1 - - [24/Jan/2020 22:51:27] "GET /api/v1/user/1/notes HTTP/1.1" 200 -
INFO:werkzeug:127.0.0.1 - - [24/Jan/2020 22:51:50] "GET /api/v1/user/1/notes HTTP/1.1" 200 -
INFO:werkzeug:127.0.0.1 - - [24/Jan/2020 22:53:06] "GET /api/v1/user/1/notes HTTP/1.1" 200 -
INFO:werkzeug:127.0.0.1 - - [24/Jan/2020 23:02:11] "OPTIONS /api/v1/user/1/notes HTTP/1.1" 200 -
INFO:werkzeug:127.0.0.1 - - [24/Jan/2020 23:02:12] "GET /api/v1/user/1/notes HTTP/1.1" 200 -
INFO:werkzeug:127.0.0.1 - - [24/Jan/2020 23:02:25] "OPTIONS /api/v1/user/1/notes HTTP/1.1" 200 -
INFO:werkzeug:127.0.0.1 - - [24/Jan/2020 23:02:26] "GET /api/v1/user/1/notes HTTP/1.1" 200 -
INFO:werkzeug:127.0.0.1 - - [24/Jan/2020 23:02:30] "OPTIONS /api/v1/user/1/notes HTTP/1.1" 200 -
INFO:werkzeug:127.0.0.1 - - [24/Jan/2020 23:02:31] "GET /api/v1/user/1/notes HTTP/1.1" 200 -
INFO:werkzeug:127.0.0.1 - - [24/Jan/2020 23:02:57] "OPTIONS /api/v1/user/1/notes HTTP/1.1" 200 -
INFO:werkzeug:127.0.0.1 - - [24/Jan/2020 23:02:57] "GET /api/v1/user/1/notes HTTP/1.1" 200 -
INFO:werkzeug:127.0.0.1 - - [24/Jan/2020 23:06:35] "GET /api/v1/user/1/notes HTTP/1.1" 200 -
ERROR:index:Exception on /api/v1/show/note/test [GET]
Traceback (most recent call last):
  File "c:\users\lubom\documents\web development\user-notes-api\venv\lib\site-packages\flask\app.py", line 2446, in wsgi_app
    response = self.full_dispatch_request()
  File "c:\users\lubom\documents\web development\user-notes-api\venv\lib\site-packages\flask\app.py", line 1951, in full_dispatch_request
    rv = self.handle_user_exception(e)
  File "c:\users\lubom\documents\web development\user-notes-api\venv\lib\site-packages\flask_cors\extension.py", line 161, in wrapped_function
    return cors_after_request(app.make_response(f(*args, **kwargs)))
  File "c:\users\lubom\documents\web development\user-notes-api\venv\lib\site-packages\flask\app.py", line 1820, in handle_user_exception
    reraise(exc_type, exc_value, tb)
  File "c:\users\lubom\documents\web development\user-notes-api\venv\lib\site-packages\flask\_compat.py", line 39, in reraise
    raise value
  File "c:\users\lubom\documents\web development\user-notes-api\venv\lib\site-packages\flask\app.py", line 1949, in full_dispatch_request
    rv = self.dispatch_request()
  File "c:\users\lubom\documents\web development\user-notes-api\venv\lib\site-packages\flask\app.py", line 1935, in dispatch_request
    return self.view_functions[rule.endpoint](**req.view_args)
  File "C:\Users\lubom\Documents\Web Development\User-Notes-Api\index.py", line 22, in show_note
    note = DBHelpers().see_note(slug)
  File "C:\Users\lubom\Documents\Web Development\User-Notes-Api\dbhelpers.py", line 16, in see_note
    self.mysql.execute("SELECT * FROM {} WHERE slug={} LIMIT 1".format(self.database.get_notes_table_name(),note_slug))
AttributeError: 'Database' object has no attribute 'get_notes_table_name'
INFO:werkzeug:127.0.0.1 - - [24/Jan/2020 23:07:53] "GET /api/v1/show/note/test HTTP/1.1" 500 -
INFO:werkzeug:127.0.0.1 - - [24/Jan/2020 23:07:53] "GET /favicon.ico HTTP/1.1" 404 -
ERROR:index:Exception on /api/v1/show/note/test [GET]
Traceback (most recent call last):
  File "c:\users\lubom\documents\web development\user-notes-api\venv\lib\site-packages\flask\app.py", line 2446, in wsgi_app
    response = self.full_dispatch_request()
  File "c:\users\lubom\documents\web development\user-notes-api\venv\lib\site-packages\flask\app.py", line 1951, in full_dispatch_request
    rv = self.handle_user_exception(e)
  File "c:\users\lubom\documents\web development\user-notes-api\venv\lib\site-packages\flask_cors\extension.py", line 161, in wrapped_function
    return cors_after_request(app.make_response(f(*args, **kwargs)))
  File "c:\users\lubom\documents\web development\user-notes-api\venv\lib\site-packages\flask\app.py", line 1820, in handle_user_exception
    reraise(exc_type, exc_value, tb)
  File "c:\users\lubom\documents\web development\user-notes-api\venv\lib\site-packages\flask\_compat.py", line 39, in reraise
    raise value
  File "c:\users\lubom\documents\web development\user-notes-api\venv\lib\site-packages\flask\app.py", line 1949, in full_dispatch_request
    rv = self.dispatch_request()
  File "c:\users\lubom\documents\web development\user-notes-api\venv\lib\site-packages\flask\app.py", line 1935, in dispatch_request
    return self.view_functions[rule.endpoint](**req.view_args)
  File "C:\Users\lubom\Documents\Web Development\User-Notes-Api\index.py", line 22, in show_note
    note = DBHelpers().see_note(slug)
  File "C:\Users\lubom\Documents\Web Development\User-Notes-Api\dbhelpers.py", line 16, in see_note
    self.mysql.execute("SELECT * FROM {}notes WHERE slug={} LIMIT 1".format(os.getenv('DATABASE_PREFIX'),note_slug))
  File "c:\users\lubom\documents\web development\user-notes-api\venv\lib\site-packages\pymysql\cursors.py", line 170, in execute
    result = self._query(query)
  File "c:\users\lubom\documents\web development\user-notes-api\venv\lib\site-packages\pymysql\cursors.py", line 328, in _query
    conn.query(q)
  File "c:\users\lubom\documents\web development\user-notes-api\venv\lib\site-packages\pymysql\connections.py", line 517, in query
    self._affected_rows = self._read_query_result(unbuffered=unbuffered)
  File "c:\users\lubom\documents\web development\user-notes-api\venv\lib\site-packages\pymysql\connections.py", line 732, in _read_query_result
    result.read()
  File "c:\users\lubom\documents\web development\user-notes-api\venv\lib\site-packages\pymysql\connections.py", line 1075, in read
    first_packet = self.connection._read_packet()
  File "c:\users\lubom\documents\web development\user-notes-api\venv\lib\site-packages\pymysql\connections.py", line 684, in _read_packet
    packet.check_error()
  File "c:\users\lubom\documents\web development\user-notes-api\venv\lib\site-packages\pymysql\protocol.py", line 220, in check_error
    err.raise_mysql_exception(self._data)
  File "c:\users\lubom\documents\web development\user-notes-api\venv\lib\site-packages\pymysql\err.py", line 109, in raise_mysql_exception
    raise errorclass(errno, errval)
pymysql.err.InternalError: (1054, "Unknown column 'test' in 'where clause'")
INFO:werkzeug:127.0.0.1 - - [24/Jan/2020 23:08:37] "GET /api/v1/show/note/test HTTP/1.1" 500 -
ERROR:index:Exception on /api/v1/show/note/test [GET]
Traceback (most recent call last):
  File "c:\users\lubom\documents\web development\user-notes-api\venv\lib\site-packages\flask\app.py", line 2446, in wsgi_app
    response = self.full_dispatch_request()
  File "c:\users\lubom\documents\web development\user-notes-api\venv\lib\site-packages\flask\app.py", line 1951, in full_dispatch_request
    rv = self.handle_user_exception(e)
  File "c:\users\lubom\documents\web development\user-notes-api\venv\lib\site-packages\flask_cors\extension.py", line 161, in wrapped_function
    return cors_after_request(app.make_response(f(*args, **kwargs)))
  File "c:\users\lubom\documents\web development\user-notes-api\venv\lib\site-packages\flask\app.py", line 1820, in handle_user_exception
    reraise(exc_type, exc_value, tb)
  File "c:\users\lubom\documents\web development\user-notes-api\venv\lib\site-packages\flask\_compat.py", line 39, in reraise
    raise value
  File "c:\users\lubom\documents\web development\user-notes-api\venv\lib\site-packages\flask\app.py", line 1949, in full_dispatch_request
    rv = self.dispatch_request()
  File "c:\users\lubom\documents\web development\user-notes-api\venv\lib\site-packages\flask\app.py", line 1935, in dispatch_request
    return self.view_functions[rule.endpoint](**req.view_args)
  File "C:\Users\lubom\Documents\Web Development\User-Notes-Api\index.py", line 22, in show_note
    note = DBHelpers().see_note(slug)
  File "C:\Users\lubom\Documents\Web Development\User-Notes-Api\dbhelpers.py", line 16, in see_note
    self.mysql.execute("SELECT * FROM {}notes WHERE slug=`{}`".format(os.getenv('DATABASE_PREFIX'),note_slug))
  File "c:\users\lubom\documents\web development\user-notes-api\venv\lib\site-packages\pymysql\cursors.py", line 170, in execute
    result = self._query(query)
  File "c:\users\lubom\documents\web development\user-notes-api\venv\lib\site-packages\pymysql\cursors.py", line 328, in _query
    conn.query(q)
  File "c:\users\lubom\documents\web development\user-notes-api\venv\lib\site-packages\pymysql\connections.py", line 517, in query
    self._affected_rows = self._read_query_result(unbuffered=unbuffered)
  File "c:\users\lubom\documents\web development\user-notes-api\venv\lib\site-packages\pymysql\connections.py", line 732, in _read_query_result
    result.read()
  File "c:\users\lubom\documents\web development\user-notes-api\venv\lib\site-packages\pymysql\connections.py", line 1075, in read
    first_packet = self.connection._read_packet()
  File "c:\users\lubom\documents\web development\user-notes-api\venv\lib\site-packages\pymysql\connections.py", line 684, in _read_packet
    packet.check_error()
  File "c:\users\lubom\documents\web development\user-notes-api\venv\lib\site-packages\pymysql\protocol.py", line 220, in check_error
    err.raise_mysql_exception(self._data)
  File "c:\users\lubom\documents\web development\user-notes-api\venv\lib\site-packages\pymysql\err.py", line 109, in raise_mysql_exception
    raise errorclass(errno, errval)
pymysql.err.InternalError: (1054, "Unknown column 'test' in 'where clause'")
INFO:werkzeug:127.0.0.1 - - [24/Jan/2020 23:10:28] "GET /api/v1/show/note/test HTTP/1.1" 500 -
INFO:werkzeug:127.0.0.1 - - [24/Jan/2020 23:10:29] "GET /favicon.ico HTTP/1.1" 404 -
ERROR:index:Exception on /api/v1/show/note/test [GET]
Traceback (most recent call last):
  File "c:\users\lubom\documents\web development\user-notes-api\venv\lib\site-packages\flask\app.py", line 2446, in wsgi_app
    response = self.full_dispatch_request()
  File "c:\users\lubom\documents\web development\user-notes-api\venv\lib\site-packages\flask\app.py", line 1951, in full_dispatch_request
    rv = self.handle_user_exception(e)
  File "c:\users\lubom\documents\web development\user-notes-api\venv\lib\site-packages\flask_cors\extension.py", line 161, in wrapped_function
    return cors_after_request(app.make_response(f(*args, **kwargs)))
  File "c:\users\lubom\documents\web development\user-notes-api\venv\lib\site-packages\flask\app.py", line 1820, in handle_user_exception
    reraise(exc_type, exc_value, tb)
  File "c:\users\lubom\documents\web development\user-notes-api\venv\lib\site-packages\flask\_compat.py", line 39, in reraise
    raise value
  File "c:\users\lubom\documents\web development\user-notes-api\venv\lib\site-packages\flask\app.py", line 1949, in full_dispatch_request
    rv = self.dispatch_request()
  File "c:\users\lubom\documents\web development\user-notes-api\venv\lib\site-packages\flask\app.py", line 1935, in dispatch_request
    return self.view_functions[rule.endpoint](**req.view_args)
  File "C:\Users\lubom\Documents\Web Development\User-Notes-Api\index.py", line 22, in show_note
    note = DBHelpers().see_note(slug)
  File "C:\Users\lubom\Documents\Web Development\User-Notes-Api\dbhelpers.py", line 16, in see_note
    self.mysql.execute("SELECT * FROM {}notes WHERE slug LIKE {} LIMIT 1".format(os.getenv('DATABASE_PREFIX'),note_slug))
  File "c:\users\lubom\documents\web development\user-notes-api\venv\lib\site-packages\pymysql\cursors.py", line 170, in execute
    result = self._query(query)
  File "c:\users\lubom\documents\web development\user-notes-api\venv\lib\site-packages\pymysql\cursors.py", line 328, in _query
    conn.query(q)
  File "c:\users\lubom\documents\web development\user-notes-api\venv\lib\site-packages\pymysql\connections.py", line 517, in query
    self._affected_rows = self._read_query_result(unbuffered=unbuffered)
  File "c:\users\lubom\documents\web development\user-notes-api\venv\lib\site-packages\pymysql\connections.py", line 732, in _read_query_result
    result.read()
  File "c:\users\lubom\documents\web development\user-notes-api\venv\lib\site-packages\pymysql\connections.py", line 1075, in read
    first_packet = self.connection._read_packet()
  File "c:\users\lubom\documents\web development\user-notes-api\venv\lib\site-packages\pymysql\connections.py", line 684, in _read_packet
    packet.check_error()
  File "c:\users\lubom\documents\web development\user-notes-api\venv\lib\site-packages\pymysql\protocol.py", line 220, in check_error
    err.raise_mysql_exception(self._data)
  File "c:\users\lubom\documents\web development\user-notes-api\venv\lib\site-packages\pymysql\err.py", line 109, in raise_mysql_exception
    raise errorclass(errno, errval)
pymysql.err.InternalError: (1054, "Unknown column 'test' in 'where clause'")
INFO:werkzeug:127.0.0.1 - - [24/Jan/2020 23:12:51] "GET /api/v1/show/note/test HTTP/1.1" 500 -
INFO:werkzeug:127.0.0.1 - - [24/Jan/2020 23:12:51] "GET /favicon.ico HTTP/1.1" 404 -
ERROR:index:Exception on /api/v1/show/note/test [GET]
Traceback (most recent call last):
  File "c:\users\lubom\documents\web development\user-notes-api\venv\lib\site-packages\flask\app.py", line 2446, in wsgi_app
    response = self.full_dispatch_request()
  File "c:\users\lubom\documents\web development\user-notes-api\venv\lib\site-packages\flask\app.py", line 1951, in full_dispatch_request
    rv = self.handle_user_exception(e)
  File "c:\users\lubom\documents\web development\user-notes-api\venv\lib\site-packages\flask_cors\extension.py", line 161, in wrapped_function
    return cors_after_request(app.make_response(f(*args, **kwargs)))
  File "c:\users\lubom\documents\web development\user-notes-api\venv\lib\site-packages\flask\app.py", line 1820, in handle_user_exception
    reraise(exc_type, exc_value, tb)
  File "c:\users\lubom\documents\web development\user-notes-api\venv\lib\site-packages\flask\_compat.py", line 39, in reraise
    raise value
  File "c:\users\lubom\documents\web development\user-notes-api\venv\lib\site-packages\flask\app.py", line 1949, in full_dispatch_request
    rv = self.dispatch_request()
  File "c:\users\lubom\documents\web development\user-notes-api\venv\lib\site-packages\flask\app.py", line 1935, in dispatch_request
    return self.view_functions[rule.endpoint](**req.view_args)
  File "C:\Users\lubom\Documents\Web Development\User-Notes-Api\index.py", line 22, in show_note
    note = DBHelpers().see_note(slug)
  File "C:\Users\lubom\Documents\Web Development\User-Notes-Api\dbhelpers.py", line 16, in see_note
    self.mysql.execute("SELECT * FROM {}notes WHERE slug LIKE {} LIMIT 1".format(os.getenv('DATABASE_PREFIX'),note_slug))
  File "c:\users\lubom\documents\web development\user-notes-api\venv\lib\site-packages\pymysql\cursors.py", line 170, in execute
    result = self._query(query)
  File "c:\users\lubom\documents\web development\user-notes-api\venv\lib\site-packages\pymysql\cursors.py", line 328, in _query
    conn.query(q)
  File "c:\users\lubom\documents\web development\user-notes-api\venv\lib\site-packages\pymysql\connections.py", line 517, in query
    self._affected_rows = self._read_query_result(unbuffered=unbuffered)
  File "c:\users\lubom\documents\web development\user-notes-api\venv\lib\site-packages\pymysql\connections.py", line 732, in _read_query_result
    result.read()
  File "c:\users\lubom\documents\web development\user-notes-api\venv\lib\site-packages\pymysql\connections.py", line 1075, in read
    first_packet = self.connection._read_packet()
  File "c:\users\lubom\documents\web development\user-notes-api\venv\lib\site-packages\pymysql\connections.py", line 684, in _read_packet
    packet.check_error()
  File "c:\users\lubom\documents\web development\user-notes-api\venv\lib\site-packages\pymysql\protocol.py", line 220, in check_error
    err.raise_mysql_exception(self._data)
  File "c:\users\lubom\documents\web development\user-notes-api\venv\lib\site-packages\pymysql\err.py", line 109, in raise_mysql_exception
    raise errorclass(errno, errval)
pymysql.err.InternalError: (1054, "Unknown column 'test' in 'where clause'")
INFO:werkzeug:127.0.0.1 - - [24/Jan/2020 23:14:30] "GET /api/v1/show/note/test HTTP/1.1" 500 -
ERROR:index:Exception on /api/v1/show/note/test [GET]
Traceback (most recent call last):
  File "c:\users\lubom\documents\web development\user-notes-api\venv\lib\site-packages\flask\app.py", line 2446, in wsgi_app
    response = self.full_dispatch_request()
  File "c:\users\lubom\documents\web development\user-notes-api\venv\lib\site-packages\flask\app.py", line 1951, in full_dispatch_request
    rv = self.handle_user_exception(e)
  File "c:\users\lubom\documents\web development\user-notes-api\venv\lib\site-packages\flask_cors\extension.py", line 161, in wrapped_function
    return cors_after_request(app.make_response(f(*args, **kwargs)))
  File "c:\users\lubom\documents\web development\user-notes-api\venv\lib\site-packages\flask\app.py", line 1820, in handle_user_exception
    reraise(exc_type, exc_value, tb)
  File "c:\users\lubom\documents\web development\user-notes-api\venv\lib\site-packages\flask\_compat.py", line 39, in reraise
    raise value
  File "c:\users\lubom\documents\web development\user-notes-api\venv\lib\site-packages\flask\app.py", line 1949, in full_dispatch_request
    rv = self.dispatch_request()
  File "c:\users\lubom\documents\web development\user-notes-api\venv\lib\site-packages\flask\app.py", line 1935, in dispatch_request
    return self.view_functions[rule.endpoint](**req.view_args)
  File "C:\Users\lubom\Documents\Web Development\User-Notes-Api\index.py", line 22, in show_note
    note = DBHelpers().see_note(slug)
  File "C:\Users\lubom\Documents\Web Development\User-Notes-Api\dbhelpers.py", line 16, in see_note
    self.mysql.execute("SELECT * FROM {}notes WHERE slug={}".format(os.getenv('DATABASE_PREFIX'),str(note_slug)))
  File "c:\users\lubom\documents\web development\user-notes-api\venv\lib\site-packages\pymysql\cursors.py", line 170, in execute
    result = self._query(query)
  File "c:\users\lubom\documents\web development\user-notes-api\venv\lib\site-packages\pymysql\cursors.py", line 328, in _query
    conn.query(q)
  File "c:\users\lubom\documents\web development\user-notes-api\venv\lib\site-packages\pymysql\connections.py", line 517, in query
    self._affected_rows = self._read_query_result(unbuffered=unbuffered)
  File "c:\users\lubom\documents\web development\user-notes-api\venv\lib\site-packages\pymysql\connections.py", line 732, in _read_query_result
    result.read()
  File "c:\users\lubom\documents\web development\user-notes-api\venv\lib\site-packages\pymysql\connections.py", line 1075, in read
    first_packet = self.connection._read_packet()
  File "c:\users\lubom\documents\web development\user-notes-api\venv\lib\site-packages\pymysql\connections.py", line 684, in _read_packet
    packet.check_error()
  File "c:\users\lubom\documents\web development\user-notes-api\venv\lib\site-packages\pymysql\protocol.py", line 220, in check_error
    err.raise_mysql_exception(self._data)
  File "c:\users\lubom\documents\web development\user-notes-api\venv\lib\site-packages\pymysql\err.py", line 109, in raise_mysql_exception
    raise errorclass(errno, errval)
pymysql.err.InternalError: (1054, "Unknown column 'test' in 'where clause'")
INFO:werkzeug:127.0.0.1 - - [24/Jan/2020 23:15:32] "GET /api/v1/show/note/test HTTP/1.1" 500 -
INFO:werkzeug:127.0.0.1 - - [24/Jan/2020 23:15:32] "GET /favicon.ico HTTP/1.1" 404 -
ERROR:index:Exception on /api/v1/show/note/test [GET]
Traceback (most recent call last):
  File "c:\users\lubom\documents\web development\user-notes-api\venv\lib\site-packages\flask\app.py", line 2446, in wsgi_app
    response = self.full_dispatch_request()
  File "c:\users\lubom\documents\web development\user-notes-api\venv\lib\site-packages\flask\app.py", line 1951, in full_dispatch_request
    rv = self.handle_user_exception(e)
  File "c:\users\lubom\documents\web development\user-notes-api\venv\lib\site-packages\flask_cors\extension.py", line 161, in wrapped_function
    return cors_after_request(app.make_response(f(*args, **kwargs)))
  File "c:\users\lubom\documents\web development\user-notes-api\venv\lib\site-packages\flask\app.py", line 1820, in handle_user_exception
    reraise(exc_type, exc_value, tb)
  File "c:\users\lubom\documents\web development\user-notes-api\venv\lib\site-packages\flask\_compat.py", line 39, in reraise
    raise value
  File "c:\users\lubom\documents\web development\user-notes-api\venv\lib\site-packages\flask\app.py", line 1949, in full_dispatch_request
    rv = self.dispatch_request()
  File "c:\users\lubom\documents\web development\user-notes-api\venv\lib\site-packages\flask\app.py", line 1935, in dispatch_request
    return self.view_functions[rule.endpoint](**req.view_args)
  File "C:\Users\lubom\Documents\Web Development\User-Notes-Api\index.py", line 24, in show_note
    if note.public == 0:
AttributeError: 'dict' object has no attribute 'public'
INFO:werkzeug:127.0.0.1 - - [24/Jan/2020 23:17:09] "GET /api/v1/show/note/test HTTP/1.1" 500 -
ERROR:index:Exception on /api/v1/show/note/test [GET]
Traceback (most recent call last):
  File "c:\users\lubom\documents\web development\user-notes-api\venv\lib\site-packages\flask\app.py", line 2446, in wsgi_app
    response = self.full_dispatch_request()
  File "c:\users\lubom\documents\web development\user-notes-api\venv\lib\site-packages\flask\app.py", line 1951, in full_dispatch_request
    rv = self.handle_user_exception(e)
  File "c:\users\lubom\documents\web development\user-notes-api\venv\lib\site-packages\flask_cors\extension.py", line 161, in wrapped_function
    return cors_after_request(app.make_response(f(*args, **kwargs)))
  File "c:\users\lubom\documents\web development\user-notes-api\venv\lib\site-packages\flask\app.py", line 1820, in handle_user_exception
    reraise(exc_type, exc_value, tb)
  File "c:\users\lubom\documents\web development\user-notes-api\venv\lib\site-packages\flask\_compat.py", line 39, in reraise
    raise value
  File "c:\users\lubom\documents\web development\user-notes-api\venv\lib\site-packages\flask\app.py", line 1949, in full_dispatch_request
    rv = self.dispatch_request()
  File "c:\users\lubom\documents\web development\user-notes-api\venv\lib\site-packages\flask\app.py", line 1935, in dispatch_request
    return self.view_functions[rule.endpoint](**req.view_args)
  File "C:\Users\lubom\Documents\Web Development\User-Notes-Api\index.py", line 24, in show_note
    if note.public == 0:
AttributeError: 'dict' object has no attribute 'public'
INFO:werkzeug:127.0.0.1 - - [24/Jan/2020 23:17:10] "GET /api/v1/show/note/test HTTP/1.1" 500 -
ERROR:index:Exception on /api/v1/show/note/test [GET]
Traceback (most recent call last):
  File "c:\users\lubom\documents\web development\user-notes-api\venv\lib\site-packages\flask\app.py", line 2446, in wsgi_app
    response = self.full_dispatch_request()
  File "c:\users\lubom\documents\web development\user-notes-api\venv\lib\site-packages\flask\app.py", line 1951, in full_dispatch_request
    rv = self.handle_user_exception(e)
  File "c:\users\lubom\documents\web development\user-notes-api\venv\lib\site-packages\flask_cors\extension.py", line 161, in wrapped_function
    return cors_after_request(app.make_response(f(*args, **kwargs)))
  File "c:\users\lubom\documents\web development\user-notes-api\venv\lib\site-packages\flask\app.py", line 1820, in handle_user_exception
    reraise(exc_type, exc_value, tb)
  File "c:\users\lubom\documents\web development\user-notes-api\venv\lib\site-packages\flask\_compat.py", line 39, in reraise
    raise value
  File "c:\users\lubom\documents\web development\user-notes-api\venv\lib\site-packages\flask\app.py", line 1949, in full_dispatch_request
    rv = self.dispatch_request()
  File "c:\users\lubom\documents\web development\user-notes-api\venv\lib\site-packages\flask\app.py", line 1935, in dispatch_request
    return self.view_functions[rule.endpoint](**req.view_args)
  File "C:\Users\lubom\Documents\Web Development\User-Notes-Api\index.py", line 25, in show_note
    if note.public == 0:
AttributeError: 'dict' object has no attribute 'public'
INFO:werkzeug:127.0.0.1 - - [24/Jan/2020 23:17:51] "GET /api/v1/show/note/test HTTP/1.1" 500 -
ERROR:index:Exception on /api/v1/show/note/test [GET]
Traceback (most recent call last):
  File "c:\users\lubom\documents\web development\user-notes-api\venv\lib\site-packages\flask\app.py", line 2446, in wsgi_app
    response = self.full_dispatch_request()
  File "c:\users\lubom\documents\web development\user-notes-api\venv\lib\site-packages\flask\app.py", line 1951, in full_dispatch_request
    rv = self.handle_user_exception(e)
  File "c:\users\lubom\documents\web development\user-notes-api\venv\lib\site-packages\flask_cors\extension.py", line 161, in wrapped_function
    return cors_after_request(app.make_response(f(*args, **kwargs)))
  File "c:\users\lubom\documents\web development\user-notes-api\venv\lib\site-packages\flask\app.py", line 1820, in handle_user_exception
    reraise(exc_type, exc_value, tb)
  File "c:\users\lubom\documents\web development\user-notes-api\venv\lib\site-packages\flask\_compat.py", line 39, in reraise
    raise value
  File "c:\users\lubom\documents\web development\user-notes-api\venv\lib\site-packages\flask\app.py", line 1949, in full_dispatch_request
    rv = self.dispatch_request()
  File "c:\users\lubom\documents\web development\user-notes-api\venv\lib\site-packages\flask\app.py", line 1935, in dispatch_request
    return self.view_functions[rule.endpoint](**req.view_args)
  File "C:\Users\lubom\Documents\Web Development\User-Notes-Api\index.py", line 25, in show_note
    if note.public == 0:
AttributeError: 'dict' object has no attribute 'public'
INFO:werkzeug:127.0.0.1 - - [24/Jan/2020 23:18:15] "GET /api/v1/show/note/test HTTP/1.1" 500 -
INFO:werkzeug:127.0.0.1 - - [24/Jan/2020 23:18:30] "GET /api/v1/show/note/test HTTP/1.1" 200 -
INFO:werkzeug:127.0.0.1 - - [24/Jan/2020 23:19:15] "GET /api/v1/show/note/test HTTP/1.1" 200 -
INFO:werkzeug:127.0.0.1 - - [24/Jan/2020 23:19:19] "GET /api/v1/show/note/test HTTP/1.1" 200 -
ERROR:index:Exception on /api/v1/show/note/test [GET]
Traceback (most recent call last):
  File "c:\users\lubom\documents\web development\user-notes-api\venv\lib\site-packages\flask\app.py", line 2446, in wsgi_app
    response = self.full_dispatch_request()
  File "c:\users\lubom\documents\web development\user-notes-api\venv\lib\site-packages\flask\app.py", line 1951, in full_dispatch_request
    rv = self.handle_user_exception(e)
  File "c:\users\lubom\documents\web development\user-notes-api\venv\lib\site-packages\flask_cors\extension.py", line 161, in wrapped_function
    return cors_after_request(app.make_response(f(*args, **kwargs)))
  File "c:\users\lubom\documents\web development\user-notes-api\venv\lib\site-packages\flask\app.py", line 1820, in handle_user_exception
    reraise(exc_type, exc_value, tb)
  File "c:\users\lubom\documents\web development\user-notes-api\venv\lib\site-packages\flask\_compat.py", line 39, in reraise
    raise value
  File "c:\users\lubom\documents\web development\user-notes-api\venv\lib\site-packages\flask\app.py", line 1949, in full_dispatch_request
    rv = self.dispatch_request()
  File "c:\users\lubom\documents\web development\user-notes-api\venv\lib\site-packages\flask\app.py", line 1935, in dispatch_request
    return self.view_functions[rule.endpoint](**req.view_args)
  File "C:\Users\lubom\Documents\Web Development\User-Notes-Api\index.py", line 25, in show_note
    return jsonify(note).public
AttributeError: 'Response' object has no attribute 'public'
INFO:werkzeug:127.0.0.1 - - [24/Jan/2020 23:19:38] "GET /api/v1/show/note/test HTTP/1.1" 500 -
INFO:werkzeug:127.0.0.1 - - [24/Jan/2020 23:19:56] "GET /api/v1/show/note/test HTTP/1.1" 200 -
ERROR:index:Exception on /api/v1/show/note/test [GET]
Traceback (most recent call last):
  File "c:\users\lubom\documents\web development\user-notes-api\venv\lib\site-packages\flask\app.py", line 2446, in wsgi_app
    response = self.full_dispatch_request()
  File "c:\users\lubom\documents\web development\user-notes-api\venv\lib\site-packages\flask\app.py", line 1951, in full_dispatch_request
    rv = self.handle_user_exception(e)
  File "c:\users\lubom\documents\web development\user-notes-api\venv\lib\site-packages\flask_cors\extension.py", line 161, in wrapped_function
    return cors_after_request(app.make_response(f(*args, **kwargs)))
  File "c:\users\lubom\documents\web development\user-notes-api\venv\lib\site-packages\flask\app.py", line 1820, in handle_user_exception
    reraise(exc_type, exc_value, tb)
  File "c:\users\lubom\documents\web development\user-notes-api\venv\lib\site-packages\flask\_compat.py", line 39, in reraise
    raise value
  File "c:\users\lubom\documents\web development\user-notes-api\venv\lib\site-packages\flask\app.py", line 1949, in full_dispatch_request
    rv = self.dispatch_request()
  File "c:\users\lubom\documents\web development\user-notes-api\venv\lib\site-packages\flask\app.py", line 1935, in dispatch_request
    return self.view_functions[rule.endpoint](**req.view_args)
  File "C:\Users\lubom\Documents\Web Development\User-Notes-Api\index.py", line 27, in show_note
    return note.public
AttributeError: 'dict' object has no attribute 'public'
INFO:werkzeug:127.0.0.1 - - [24/Jan/2020 23:21:42] "GET /api/v1/show/note/test HTTP/1.1" 500 -
INFO:werkzeug:127.0.0.1 - - [24/Jan/2020 23:21:42] "GET /favicon.ico HTTP/1.1" 404 -
INFO:werkzeug:127.0.0.1 - - [24/Jan/2020 23:22:02] "GET /api/v1/show/note/test HTTP/1.1" 200 -
ERROR:index:Exception on /api/v1/show/note/test [GET]
Traceback (most recent call last):
  File "c:\users\lubom\documents\web development\user-notes-api\venv\lib\site-packages\flask\app.py", line 2446, in wsgi_app
    response = self.full_dispatch_request()
  File "c:\users\lubom\documents\web development\user-notes-api\venv\lib\site-packages\flask\app.py", line 1951, in full_dispatch_request
    rv = self.handle_user_exception(e)
  File "c:\users\lubom\documents\web development\user-notes-api\venv\lib\site-packages\flask_cors\extension.py", line 161, in wrapped_function
    return cors_after_request(app.make_response(f(*args, **kwargs)))
  File "c:\users\lubom\documents\web development\user-notes-api\venv\lib\site-packages\flask\app.py", line 1820, in handle_user_exception
    reraise(exc_type, exc_value, tb)
  File "c:\users\lubom\documents\web development\user-notes-api\venv\lib\site-packages\flask\_compat.py", line 39, in reraise
    raise value
  File "c:\users\lubom\documents\web development\user-notes-api\venv\lib\site-packages\flask\app.py", line 1949, in full_dispatch_request
    rv = self.dispatch_request()
  File "c:\users\lubom\documents\web development\user-notes-api\venv\lib\site-packages\flask\app.py", line 1935, in dispatch_request
    return self.view_functions[rule.endpoint](**req.view_args)
  File "C:\Users\lubom\Documents\Web Development\User-Notes-Api\index.py", line 24, in show_note
    json.loads(note)
  File "C:\Users\lubom\AppData\Local\Programs\Python\Python38\lib\json\__init__.py", line 341, in loads
    raise TypeError(f'the JSON object must be str, bytes or bytearray, '
TypeError: the JSON object must be str, bytes or bytearray, not dict
INFO:werkzeug:127.0.0.1 - - [24/Jan/2020 23:27:57] "GET /api/v1/show/note/test HTTP/1.1" 500 -
ERROR:index:Exception on /api/v1/show/note/test [GET]
Traceback (most recent call last):
  File "c:\users\lubom\documents\web development\user-notes-api\venv\lib\site-packages\flask\app.py", line 2446, in wsgi_app
    response = self.full_dispatch_request()
  File "c:\users\lubom\documents\web development\user-notes-api\venv\lib\site-packages\flask\app.py", line 1951, in full_dispatch_request
    rv = self.handle_user_exception(e)
  File "c:\users\lubom\documents\web development\user-notes-api\venv\lib\site-packages\flask_cors\extension.py", line 161, in wrapped_function
    return cors_after_request(app.make_response(f(*args, **kwargs)))
  File "c:\users\lubom\documents\web development\user-notes-api\venv\lib\site-packages\flask\app.py", line 1820, in handle_user_exception
    reraise(exc_type, exc_value, tb)
  File "c:\users\lubom\documents\web development\user-notes-api\venv\lib\site-packages\flask\_compat.py", line 39, in reraise
    raise value
  File "c:\users\lubom\documents\web development\user-notes-api\venv\lib\site-packages\flask\app.py", line 1949, in full_dispatch_request
    rv = self.dispatch_request()
  File "c:\users\lubom\documents\web development\user-notes-api\venv\lib\site-packages\flask\app.py", line 1935, in dispatch_request
    return self.view_functions[rule.endpoint](**req.view_args)
  File "C:\Users\lubom\Documents\Web Development\User-Notes-Api\index.py", line 24, in show_note
    note = json.loads(note)
UnboundLocalError: local variable 'note' referenced before assignment
INFO:werkzeug:127.0.0.1 - - [24/Jan/2020 23:29:27] "GET /api/v1/show/note/test HTTP/1.1" 500 -
ERROR:index:Exception on /api/v1/show/note/test [GET]
Traceback (most recent call last):
  File "c:\users\lubom\documents\web development\user-notes-api\venv\lib\site-packages\flask\app.py", line 2446, in wsgi_app
    response = self.full_dispatch_request()
  File "c:\users\lubom\documents\web development\user-notes-api\venv\lib\site-packages\flask\app.py", line 1951, in full_dispatch_request
    rv = self.handle_user_exception(e)
  File "c:\users\lubom\documents\web development\user-notes-api\venv\lib\site-packages\flask_cors\extension.py", line 161, in wrapped_function
    return cors_after_request(app.make_response(f(*args, **kwargs)))
  File "c:\users\lubom\documents\web development\user-notes-api\venv\lib\site-packages\flask\app.py", line 1820, in handle_user_exception
    reraise(exc_type, exc_value, tb)
  File "c:\users\lubom\documents\web development\user-notes-api\venv\lib\site-packages\flask\_compat.py", line 39, in reraise
    raise value
  File "c:\users\lubom\documents\web development\user-notes-api\venv\lib\site-packages\flask\app.py", line 1949, in full_dispatch_request
    rv = self.dispatch_request()
  File "c:\users\lubom\documents\web development\user-notes-api\venv\lib\site-packages\flask\app.py", line 1935, in dispatch_request
    return self.view_functions[rule.endpoint](**req.view_args)
  File "C:\Users\lubom\Documents\Web Development\User-Notes-Api\index.py", line 24, in show_note
    note = json.loads(note)
UnboundLocalError: local variable 'note' referenced before assignment
INFO:werkzeug:127.0.0.1 - - [24/Jan/2020 23:29:28] "GET /api/v1/show/note/test HTTP/1.1" 500 -
ERROR:index:Exception on /api/v1/show/note/test [GET]
Traceback (most recent call last):
  File "c:\users\lubom\documents\web development\user-notes-api\venv\lib\site-packages\flask\app.py", line 2446, in wsgi_app
    response = self.full_dispatch_request()
  File "c:\users\lubom\documents\web development\user-notes-api\venv\lib\site-packages\flask\app.py", line 1951, in full_dispatch_request
    rv = self.handle_user_exception(e)
  File "c:\users\lubom\documents\web development\user-notes-api\venv\lib\site-packages\flask_cors\extension.py", line 161, in wrapped_function
    return cors_after_request(app.make_response(f(*args, **kwargs)))
  File "c:\users\lubom\documents\web development\user-notes-api\venv\lib\site-packages\flask\app.py", line 1820, in handle_user_exception
    reraise(exc_type, exc_value, tb)
  File "c:\users\lubom\documents\web development\user-notes-api\venv\lib\site-packages\flask\_compat.py", line 39, in reraise
    raise value
  File "c:\users\lubom\documents\web development\user-notes-api\venv\lib\site-packages\flask\app.py", line 1949, in full_dispatch_request
    rv = self.dispatch_request()
  File "c:\users\lubom\documents\web development\user-notes-api\venv\lib\site-packages\flask\app.py", line 1935, in dispatch_request
    return self.view_functions[rule.endpoint](**req.view_args)
  File "C:\Users\lubom\Documents\Web Development\User-Notes-Api\index.py", line 24, in show_note
    note = json.loads(note)
UnboundLocalError: local variable 'note' referenced before assignment
INFO:werkzeug:127.0.0.1 - - [24/Jan/2020 23:29:28] "GET /api/v1/show/note/test HTTP/1.1" 500 -
ERROR:index:Exception on /api/v1/show/note/test [GET]
Traceback (most recent call last):
  File "c:\users\lubom\documents\web development\user-notes-api\venv\lib\site-packages\flask\app.py", line 2446, in wsgi_app
    response = self.full_dispatch_request()
  File "c:\users\lubom\documents\web development\user-notes-api\venv\lib\site-packages\flask\app.py", line 1951, in full_dispatch_request
    rv = self.handle_user_exception(e)
  File "c:\users\lubom\documents\web development\user-notes-api\venv\lib\site-packages\flask_cors\extension.py", line 161, in wrapped_function
    return cors_after_request(app.make_response(f(*args, **kwargs)))
  File "c:\users\lubom\documents\web development\user-notes-api\venv\lib\site-packages\flask\app.py", line 1820, in handle_user_exception
    reraise(exc_type, exc_value, tb)
  File "c:\users\lubom\documents\web development\user-notes-api\venv\lib\site-packages\flask\_compat.py", line 39, in reraise
    raise value
  File "c:\users\lubom\documents\web development\user-notes-api\venv\lib\site-packages\flask\app.py", line 1949, in full_dispatch_request
    rv = self.dispatch_request()
  File "c:\users\lubom\documents\web development\user-notes-api\venv\lib\site-packages\flask\app.py", line 1935, in dispatch_request
    return self.view_functions[rule.endpoint](**req.view_args)
  File "C:\Users\lubom\Documents\Web Development\User-Notes-Api\index.py", line 24, in show_note
    note = json.loads(note)
UnboundLocalError: local variable 'note' referenced before assignment
INFO:werkzeug:127.0.0.1 - - [24/Jan/2020 23:29:28] "GET /api/v1/show/note/test HTTP/1.1" 500 -
ERROR:index:Exception on /api/v1/show/note/test [GET]
Traceback (most recent call last):
  File "c:\users\lubom\documents\web development\user-notes-api\venv\lib\site-packages\flask\app.py", line 2446, in wsgi_app
    response = self.full_dispatch_request()
  File "c:\users\lubom\documents\web development\user-notes-api\venv\lib\site-packages\flask\app.py", line 1951, in full_dispatch_request
    rv = self.handle_user_exception(e)
  File "c:\users\lubom\documents\web development\user-notes-api\venv\lib\site-packages\flask_cors\extension.py", line 161, in wrapped_function
    return cors_after_request(app.make_response(f(*args, **kwargs)))
  File "c:\users\lubom\documents\web development\user-notes-api\venv\lib\site-packages\flask\app.py", line 1820, in handle_user_exception
    reraise(exc_type, exc_value, tb)
  File "c:\users\lubom\documents\web development\user-notes-api\venv\lib\site-packages\flask\_compat.py", line 39, in reraise
    raise value
  File "c:\users\lubom\documents\web development\user-notes-api\venv\lib\site-packages\flask\app.py", line 1949, in full_dispatch_request
    rv = self.dispatch_request()
  File "c:\users\lubom\documents\web development\user-notes-api\venv\lib\site-packages\flask\app.py", line 1935, in dispatch_request
    return self.view_functions[rule.endpoint](**req.view_args)
  File "C:\Users\lubom\Documents\Web Development\User-Notes-Api\index.py", line 24, in show_note
    note = json.loads(note)
UnboundLocalError: local variable 'note' referenced before assignment
INFO:werkzeug:127.0.0.1 - - [24/Jan/2020 23:29:29] "GET /api/v1/show/note/test HTTP/1.1" 500 -
ERROR:index:Exception on /api/v1/show/note/test [GET]
Traceback (most recent call last):
  File "c:\users\lubom\documents\web development\user-notes-api\venv\lib\site-packages\flask\app.py", line 2446, in wsgi_app
    response = self.full_dispatch_request()
  File "c:\users\lubom\documents\web development\user-notes-api\venv\lib\site-packages\flask\app.py", line 1951, in full_dispatch_request
    rv = self.handle_user_exception(e)
  File "c:\users\lubom\documents\web development\user-notes-api\venv\lib\site-packages\flask_cors\extension.py", line 161, in wrapped_function
    return cors_after_request(app.make_response(f(*args, **kwargs)))
  File "c:\users\lubom\documents\web development\user-notes-api\venv\lib\site-packages\flask\app.py", line 1820, in handle_user_exception
    reraise(exc_type, exc_value, tb)
  File "c:\users\lubom\documents\web development\user-notes-api\venv\lib\site-packages\flask\_compat.py", line 39, in reraise
    raise value
  File "c:\users\lubom\documents\web development\user-notes-api\venv\lib\site-packages\flask\app.py", line 1949, in full_dispatch_request
    rv = self.dispatch_request()
  File "c:\users\lubom\documents\web development\user-notes-api\venv\lib\site-packages\flask\app.py", line 1935, in dispatch_request
    return self.view_functions[rule.endpoint](**req.view_args)
  File "C:\Users\lubom\Documents\Web Development\User-Notes-Api\index.py", line 24, in show_note
    note = json.loads(note)
UnboundLocalError: local variable 'note' referenced before assignment
INFO:werkzeug:127.0.0.1 - - [24/Jan/2020 23:29:29] "GET /api/v1/show/note/test HTTP/1.1" 500 -
ERROR:index:Exception on /api/v1/show/note/test [GET]
Traceback (most recent call last):
  File "c:\users\lubom\documents\web development\user-notes-api\venv\lib\site-packages\flask\app.py", line 2446, in wsgi_app
    response = self.full_dispatch_request()
  File "c:\users\lubom\documents\web development\user-notes-api\venv\lib\site-packages\flask\app.py", line 1951, in full_dispatch_request
    rv = self.handle_user_exception(e)
  File "c:\users\lubom\documents\web development\user-notes-api\venv\lib\site-packages\flask_cors\extension.py", line 161, in wrapped_function
    return cors_after_request(app.make_response(f(*args, **kwargs)))
  File "c:\users\lubom\documents\web development\user-notes-api\venv\lib\site-packages\flask\app.py", line 1820, in handle_user_exception
    reraise(exc_type, exc_value, tb)
  File "c:\users\lubom\documents\web development\user-notes-api\venv\lib\site-packages\flask\_compat.py", line 39, in reraise
    raise value
  File "c:\users\lubom\documents\web development\user-notes-api\venv\lib\site-packages\flask\app.py", line 1949, in full_dispatch_request
    rv = self.dispatch_request()
  File "c:\users\lubom\documents\web development\user-notes-api\venv\lib\site-packages\flask\app.py", line 1935, in dispatch_request
    return self.view_functions[rule.endpoint](**req.view_args)
  File "C:\Users\lubom\Documents\Web Development\User-Notes-Api\index.py", line 24, in show_note
    note = json.loads(user_note)
  File "C:\Users\lubom\AppData\Local\Programs\Python\Python38\lib\json\__init__.py", line 341, in loads
    raise TypeError(f'the JSON object must be str, bytes or bytearray, '
TypeError: the JSON object must be str, bytes or bytearray, not dict
INFO:werkzeug:127.0.0.1 - - [24/Jan/2020 23:30:22] "GET /api/v1/show/note/test HTTP/1.1" 500 -
ERROR:index:Exception on /api/v1/show/note/test [GET]
Traceback (most recent call last):
  File "c:\users\lubom\documents\web development\user-notes-api\venv\lib\site-packages\flask\app.py", line 2446, in wsgi_app
    response = self.full_dispatch_request()
  File "c:\users\lubom\documents\web development\user-notes-api\venv\lib\site-packages\flask\app.py", line 1951, in full_dispatch_request
    rv = self.handle_user_exception(e)
  File "c:\users\lubom\documents\web development\user-notes-api\venv\lib\site-packages\flask_cors\extension.py", line 161, in wrapped_function
    return cors_after_request(app.make_response(f(*args, **kwargs)))
  File "c:\users\lubom\documents\web development\user-notes-api\venv\lib\site-packages\flask\app.py", line 1820, in handle_user_exception
    reraise(exc_type, exc_value, tb)
  File "c:\users\lubom\documents\web development\user-notes-api\venv\lib\site-packages\flask\_compat.py", line 39, in reraise
    raise value
  File "c:\users\lubom\documents\web development\user-notes-api\venv\lib\site-packages\flask\app.py", line 1949, in full_dispatch_request
    rv = self.dispatch_request()
  File "c:\users\lubom\documents\web development\user-notes-api\venv\lib\site-packages\flask\app.py", line 1935, in dispatch_request
    return self.view_functions[rule.endpoint](**req.view_args)
  File "C:\Users\lubom\Documents\Web Development\User-Notes-Api\index.py", line 24, in show_note
    note = json.loads(user_note)
  File "C:\Users\lubom\AppData\Local\Programs\Python\Python38\lib\json\__init__.py", line 341, in loads
    raise TypeError(f'the JSON object must be str, bytes or bytearray, '
TypeError: the JSON object must be str, bytes or bytearray, not dict
INFO:werkzeug:127.0.0.1 - - [24/Jan/2020 23:31:30] "GET /api/v1/show/note/test HTTP/1.1" 500 -
INFO:werkzeug:127.0.0.1 - - [24/Jan/2020 23:31:30] "GET /favicon.ico HTTP/1.1" 404 -
ERROR:index:Exception on /api/v1/show/note/test [GET]
Traceback (most recent call last):
  File "c:\users\lubom\documents\web development\user-notes-api\venv\lib\site-packages\flask\app.py", line 2446, in wsgi_app
    response = self.full_dispatch_request()
  File "c:\users\lubom\documents\web development\user-notes-api\venv\lib\site-packages\flask\app.py", line 1951, in full_dispatch_request
    rv = self.handle_user_exception(e)
  File "c:\users\lubom\documents\web development\user-notes-api\venv\lib\site-packages\flask_cors\extension.py", line 161, in wrapped_function
    return cors_after_request(app.make_response(f(*args, **kwargs)))
  File "c:\users\lubom\documents\web development\user-notes-api\venv\lib\site-packages\flask\app.py", line 1820, in handle_user_exception
    reraise(exc_type, exc_value, tb)
  File "c:\users\lubom\documents\web development\user-notes-api\venv\lib\site-packages\flask\_compat.py", line 39, in reraise
    raise value
  File "c:\users\lubom\documents\web development\user-notes-api\venv\lib\site-packages\flask\app.py", line 1949, in full_dispatch_request
    rv = self.dispatch_request()
  File "c:\users\lubom\documents\web development\user-notes-api\venv\lib\site-packages\flask\app.py", line 1935, in dispatch_request
    return self.view_functions[rule.endpoint](**req.view_args)
  File "C:\Users\lubom\Documents\Web Development\User-Notes-Api\index.py", line 24, in show_note
  File "C:\Users\lubom\AppData\Local\Programs\Python\Python38\lib\json\__init__.py", line 341, in loads
    raise TypeError(f'the JSON object must be str, bytes or bytearray, '
TypeError: the JSON object must be str, bytes or bytearray, not dict
INFO:werkzeug:127.0.0.1 - - [24/Jan/2020 23:31:57] "GET /api/v1/show/note/test HTTP/1.1" 500 -
ERROR:index:Exception on /api/v1/show/note/test [GET]
Traceback (most recent call last):
  File "c:\users\lubom\documents\web development\user-notes-api\venv\lib\site-packages\flask\app.py", line 2446, in wsgi_app
    response = self.full_dispatch_request()
  File "c:\users\lubom\documents\web development\user-notes-api\venv\lib\site-packages\flask\app.py", line 1951, in full_dispatch_request
    rv = self.handle_user_exception(e)
  File "c:\users\lubom\documents\web development\user-notes-api\venv\lib\site-packages\flask_cors\extension.py", line 161, in wrapped_function
    return cors_after_request(app.make_response(f(*args, **kwargs)))
  File "c:\users\lubom\documents\web development\user-notes-api\venv\lib\site-packages\flask\app.py", line 1820, in handle_user_exception
    reraise(exc_type, exc_value, tb)
  File "c:\users\lubom\documents\web development\user-notes-api\venv\lib\site-packages\flask\_compat.py", line 39, in reraise
    raise value
  File "c:\users\lubom\documents\web development\user-notes-api\venv\lib\site-packages\flask\app.py", line 1949, in full_dispatch_request
    rv = self.dispatch_request()
  File "c:\users\lubom\documents\web development\user-notes-api\venv\lib\site-packages\flask\app.py", line 1935, in dispatch_request
    return self.view_functions[rule.endpoint](**req.view_args)
  File "C:\Users\lubom\Documents\Web Development\User-Notes-Api\index.py", line 25, in show_note
    return jsonify(note)
NameError: name 'note' is not defined
INFO:werkzeug:127.0.0.1 - - [24/Jan/2020 23:32:06] "GET /api/v1/show/note/test HTTP/1.1" 500 -
ERROR:index:Exception on /api/v1/show/note/test [GET]
Traceback (most recent call last):
  File "c:\users\lubom\documents\web development\user-notes-api\venv\lib\site-packages\flask\app.py", line 2446, in wsgi_app
    response = self.full_dispatch_request()
  File "c:\users\lubom\documents\web development\user-notes-api\venv\lib\site-packages\flask\app.py", line 1951, in full_dispatch_request
    rv = self.handle_user_exception(e)
  File "c:\users\lubom\documents\web development\user-notes-api\venv\lib\site-packages\flask_cors\extension.py", line 161, in wrapped_function
    return cors_after_request(app.make_response(f(*args, **kwargs)))
  File "c:\users\lubom\documents\web development\user-notes-api\venv\lib\site-packages\flask\app.py", line 1820, in handle_user_exception
    reraise(exc_type, exc_value, tb)
  File "c:\users\lubom\documents\web development\user-notes-api\venv\lib\site-packages\flask\_compat.py", line 39, in reraise
    raise value
  File "c:\users\lubom\documents\web development\user-notes-api\venv\lib\site-packages\flask\app.py", line 1949, in full_dispatch_request
    rv = self.dispatch_request()
  File "c:\users\lubom\documents\web development\user-notes-api\venv\lib\site-packages\flask\app.py", line 1935, in dispatch_request
    return self.view_functions[rule.endpoint](**req.view_args)
  File "C:\Users\lubom\Documents\Web Development\User-Notes-Api\index.py", line 25, in show_note
    return jsonify(note)
NameError: name 'note' is not defined
INFO:werkzeug:127.0.0.1 - - [24/Jan/2020 23:32:06] "GET /api/v1/show/note/test HTTP/1.1" 500 -
ERROR:index:Exception on /api/v1/show/note/test [GET]
Traceback (most recent call last):
  File "c:\users\lubom\documents\web development\user-notes-api\venv\lib\site-packages\flask\app.py", line 2446, in wsgi_app
    response = self.full_dispatch_request()
  File "c:\users\lubom\documents\web development\user-notes-api\venv\lib\site-packages\flask\app.py", line 1951, in full_dispatch_request
    rv = self.handle_user_exception(e)
  File "c:\users\lubom\documents\web development\user-notes-api\venv\lib\site-packages\flask_cors\extension.py", line 161, in wrapped_function
    return cors_after_request(app.make_response(f(*args, **kwargs)))
  File "c:\users\lubom\documents\web development\user-notes-api\venv\lib\site-packages\flask\app.py", line 1820, in handle_user_exception
    reraise(exc_type, exc_value, tb)
  File "c:\users\lubom\documents\web development\user-notes-api\venv\lib\site-packages\flask\_compat.py", line 39, in reraise
    raise value
  File "c:\users\lubom\documents\web development\user-notes-api\venv\lib\site-packages\flask\app.py", line 1949, in full_dispatch_request
    rv = self.dispatch_request()
  File "c:\users\lubom\documents\web development\user-notes-api\venv\lib\site-packages\flask\app.py", line 1935, in dispatch_request
    return self.view_functions[rule.endpoint](**req.view_args)
  File "C:\Users\lubom\Documents\Web Development\User-Notes-Api\index.py", line 25, in show_note
    return jsonify(note)
NameError: name 'note' is not defined
INFO:werkzeug:127.0.0.1 - - [24/Jan/2020 23:32:07] "GET /api/v1/show/note/test HTTP/1.1" 500 -
ERROR:index:Exception on /api/v1/show/note/test [GET]
Traceback (most recent call last):
  File "c:\users\lubom\documents\web development\user-notes-api\venv\lib\site-packages\flask\app.py", line 2446, in wsgi_app
    response = self.full_dispatch_request()
  File "c:\users\lubom\documents\web development\user-notes-api\venv\lib\site-packages\flask\app.py", line 1951, in full_dispatch_request
    rv = self.handle_user_exception(e)
  File "c:\users\lubom\documents\web development\user-notes-api\venv\lib\site-packages\flask_cors\extension.py", line 161, in wrapped_function
    return cors_after_request(app.make_response(f(*args, **kwargs)))
  File "c:\users\lubom\documents\web development\user-notes-api\venv\lib\site-packages\flask\app.py", line 1820, in handle_user_exception
    reraise(exc_type, exc_value, tb)
  File "c:\users\lubom\documents\web development\user-notes-api\venv\lib\site-packages\flask\_compat.py", line 39, in reraise
    raise value
  File "c:\users\lubom\documents\web development\user-notes-api\venv\lib\site-packages\flask\app.py", line 1949, in full_dispatch_request
    rv = self.dispatch_request()
  File "c:\users\lubom\documents\web development\user-notes-api\venv\lib\site-packages\flask\app.py", line 1935, in dispatch_request
    return self.view_functions[rule.endpoint](**req.view_args)
  File "C:\Users\lubom\Documents\Web Development\User-Notes-Api\index.py", line 25, in show_note
    return jsonify(note)
NameError: name 'note' is not defined
INFO:werkzeug:127.0.0.1 - - [24/Jan/2020 23:32:10] "GET /api/v1/show/note/test HTTP/1.1" 500 -
INFO:werkzeug:127.0.0.1 - - [24/Jan/2020 23:32:28] "GET /api/v1/show/note/test HTTP/1.1" 200 -
ERROR:index:Exception on /api/v1/show/note/test [GET]
Traceback (most recent call last):
  File "c:\users\lubom\documents\web development\user-notes-api\venv\lib\site-packages\flask\app.py", line 2446, in wsgi_app
    response = self.full_dispatch_request()
  File "c:\users\lubom\documents\web development\user-notes-api\venv\lib\site-packages\flask\app.py", line 1951, in full_dispatch_request
    rv = self.handle_user_exception(e)
  File "c:\users\lubom\documents\web development\user-notes-api\venv\lib\site-packages\flask_cors\extension.py", line 161, in wrapped_function
    return cors_after_request(app.make_response(f(*args, **kwargs)))
  File "c:\users\lubom\documents\web development\user-notes-api\venv\lib\site-packages\flask\app.py", line 1820, in handle_user_exception
    reraise(exc_type, exc_value, tb)
  File "c:\users\lubom\documents\web development\user-notes-api\venv\lib\site-packages\flask\_compat.py", line 39, in reraise
    raise value
  File "c:\users\lubom\documents\web development\user-notes-api\venv\lib\site-packages\flask\app.py", line 1949, in full_dispatch_request
    rv = self.dispatch_request()
  File "c:\users\lubom\documents\web development\user-notes-api\venv\lib\site-packages\flask\app.py", line 1935, in dispatch_request
    return self.view_functions[rule.endpoint](**req.view_args)
  File "C:\Users\lubom\Documents\Web Development\User-Notes-Api\index.py", line 24, in show_note
    json_dict = json.loads(note)
  File "C:\Users\lubom\AppData\Local\Programs\Python\Python38\lib\json\__init__.py", line 341, in loads
    raise TypeError(f'the JSON object must be str, bytes or bytearray, '
TypeError: the JSON object must be str, bytes or bytearray, not dict
INFO:werkzeug:127.0.0.1 - - [24/Jan/2020 23:34:01] "GET /api/v1/show/note/test HTTP/1.1" 500 -
